<?xml version="1.0" encoding="utf-8"?>
<!-- This URDF was automatically created by SolidWorks to URDF Exporter! Originally created by Stephen Brawner (brawner@gmail.com) 
     Commit Version: 1.6.0-4-g7f85cfe  Build Version: 1.6.7995.38578
     For more information, please see http://wiki.ros.org/sw_urdf_exporter -->
<robot name="Planar">
  <link name="base">
    <inertial>
      <origin xyz="0 0 0" rpy="0 0 0" />
      <mass value="0.001" />
      <inertia ixx="0.00001" ixy="0" ixz="0" iyy="0.00001" iyz="0" izz="0.00001" />
    </inertial>
    <visual>
      <origin rpy="0 0 0" xyz="0 0 0"/>
      <geometry>
        <box size="0.001 0.001 0.001"/>
      </geometry>
      <material name="">
        <color rgba="1 1 1 0" />
      </material>
    </visual>
  </link>
  <joint name="floating_base" type="planar">
    <origin rpy="0 0 0" xyz="0 0 0"/>
    <parent link="base"/>
    <child link="Body_Link"/>
    <axis xyz="0 1 0" />
  </joint>
  <link name="Body_Link">
    <inertial>
      <origin xyz="0 0 0.03" rpy="0 0 0" />
      <mass value="0.001" />
      <inertia ixx="0.00001" ixy="0" ixz="0" iyy="0.00001" iyz="0" izz="0.00001" />
    </inertial>
    <visual>
      <origin xyz="0 0 0" rpy="0 0 0" />
      <geometry>
        <mesh filename="package://Body_Link.STL" />
      </geometry>
      <material name="">
        <color rgba="1 1 1 0" />
      </material>
    </visual>
  </link>
</robot>