<?xml version="1.0" encoding="utf-8"?>
<!-- This URDF was automatically created by SolidWorks to URDF Exporter! Originally created by Stephen Brawner (brawner@gmail.com) 
     Commit Version: 1.6.0-4-g7f85cfe  Build Version: 1.6.7995.38578
     For more information, please see http://wiki.ros.org/sw_urdf_exporter -->
<robot
  name="OneLeg2D">
  <link name="base">
    <inertial>
      <origin xyz="0 0 0" rpy="0 0 0" />
      <mass value="0.001" />
      <inertia ixx="0.00001" ixy="0" ixz="0" iyy="0.00001" iyz="0" izz="0.00001" />
    </inertial>
    <visual>
      <origin rpy="0 0 0" xyz="0 0 0"/>
      <geometry>
        <box size="0.001 0.001 0.001"/>
      </geometry>
      <material name="">
        <color rgba="1 1 1 0" />
      </material>
    </visual>
  </link>
  <joint name="floating_base" type="planar">
    <origin rpy="0 0 0" xyz="0 0 0"/>
    <parent link="base"/>
    <child link="Body_Link"/>
    <axis xyz="0 1 0" />
  </joint>
  <link name="Body_Link">
    <inertial>
      <origin
        xyz="-4.68738960327283E-07 6.84081833553076E-06 0.0299999971870418" rpy="0 0 0" />
      <mass value="120" />
      <inertia
        ixx="0.38183686549479"
        ixy="-2.85259253115318E-08"
        ixz="1.74153183689771E-07"
        iyy="0.378920595449684"
        iyz="5.02659143973226E-09"
        izz="0.751304758398737" />
    </inertial>
    <visual>
      <origin xyz="0 0 0" rpy="0 0 0" />
      <geometry>
        <mesh filename="package://OneLeg2D/meshes/Body_Link.STL" />
      </geometry>
      <material name="">
        <color rgba="1 1 1 1" />
      </material>
    </visual>
    <collision>
      <origin xyz="0 0 0" rpy="0 0 0" />
      <geometry>
        <mesh filename="package://OneLeg2D/meshes/Body_Link.STL" />
      </geometry>
    </collision>
  </link>
  <link name="Roll_Link">
    <inertial>
      <origin xyz="-3.13363478493992E-07 -3.13363478495251E-07 0.03" rpy="0 0 0" />
      <mass value="0.00247436658781711" />
      <inertia
        ixx="7.40251225622148E-08"
        ixy="2.42974557929604E-16"
        ixz="1.02097316129604E-11"
        iyy="7.40251225622148E-08"
        iyz="-1.02097316129553E-11"
        izz="1.15495108440108E-07" />
    </inertial>
    <visual>
      <origin
        xyz="0 0 0"
        rpy="0 0 0" />
      <geometry>
        <mesh
          filename="package://OneLeg2D/meshes/Roll_Link.STL" />
      </geometry>
      <material
        name="">
        <color
          rgba="1 1 1 1" />
      </material>
    </visual>
    <collision>
      <origin
        xyz="0 0 0"
        rpy="0 0 0" />
      <geometry>
        <mesh
          filename="package://OneLeg2D/meshes/Roll_Link.STL" />
      </geometry>
    </collision>
  </link>
  <joint
    name="Roll_Joint"
    type="revolute">
    <origin
      xyz="0 0 0"
      rpy="0 0 0" />
    <parent
      link="Body_Link" />
    <child
      link="Roll_Link" />
    <axis
      xyz="-1 0 0" />
    <limit
      lower="-1"
      upper="1"
      effort="0"
      velocity="0" />
  </joint>
  <link
    name="Pitch_Link">
    <inertial>
      <origin xyz="-0.0451612504225143 0.0066279647340668 -0.0624231735768729" rpy="0 0 0" />
      <mass value="10" />
      <inertia
        ixx="0.0139521713724596"
        ixy="-0.000271163847344455"
        ixz="-0.00650399627363935"
        iyy="0.018954091010817"
        iyz="-0.000555643100256628"
        izz="0.00622963959046108" />
    </inertial>
    <visual>
      <origin
        xyz="0 0 0"
        rpy="0 0 0" />
      <geometry>
        <mesh
          filename="package://OneLeg2D/meshes/Pitch_Link.STL" />
      </geometry>
      <material
        name="">
        <color
          rgba="1 1 1 1" />
      </material>
    </visual>
    <collision>
      <origin
        xyz="0 0 0"
        rpy="0 0 0" />
      <geometry>
        <mesh
          filename="package://OneLeg2D/meshes/Pitch_Link.STL" />
      </geometry>
    </collision>
  </link>
  <joint
    name="Pitch_Joint"
    type="revolute">
    <origin
      xyz="0 0 0"
      rpy="0 0 0" />
    <parent
      link="Roll_Link" />
    <child
      link="Pitch_Link" />
    <axis
      xyz="0 1 0" />
    <limit
      lower="-1"
      upper="1"
      effort="0"
      velocity="0" />
  </joint>
  <link
    name="Knee_Link">
    <inertial>
      <origin xyz="0.0539077857073315 1.33729204814838E-09 -0.0943103284457157" rpy="0 0 0" />
      <mass value="5" />
      <inertia
        ixx="0.000504047563938724"
        ixy="-3.29867672623702E-12"
        ixz="0.000275859527116135"
        iyy="0.000662718544760277"
        iyz="-2.43503043283472E-11"
        izz="0.000185094181562212" />
    </inertial>
    <visual>
      <origin
        xyz="0 0 0"
        rpy="0 0 0" />
      <geometry>
        <mesh
          filename="package://OneLeg2D/meshes/Knee_Link.STL" />
      </geometry>
      <material
        name="">
        <color
          rgba="1 1 1 1" />
      </material>
    </visual>
    <collision>
      <origin
        xyz="0 0 0"
        rpy="0 0 0" />
      <geometry>
        <mesh
          filename="package://OneLeg2D/meshes/Knee_Link.STL" />
      </geometry>
    </collision>
  </link>
  <joint
    name="Knee_Joint"
    type="continuous">
    <origin
      xyz="-0.199999999999974 -0.000499999999999992 -0.316410161513791"
      rpy="0 0 0" />
    <parent
      link="Pitch_Link" />
    <child
      link="Knee_Link" />
    <axis
      xyz="0 -1 0" />
  </joint>
  <link
    name="Foot_Link">
    <inertial>
      <origin
        xyz="-1.3356E-10 -2.5036E-05 -0.010497"
        rpy="0 0 0" />
      <mass
        value="0.10925" />
      <inertia
        ixx="3.3199E-05"
        ixy="-1.8907E-13"
        ixz="2.3284E-13"
        iyy="4.5593E-05"
        iyz="-2.4906E-09"
        izz="6.591E-05" />
    </inertial>
    <visual>
      <origin
        xyz="0 0 0"
        rpy="0 0 0" />
      <geometry>
        <mesh
          filename="package://OneLeg2D/meshes/Foot_Link.STL" />
      </geometry>
      <material
        name="">
        <color
          rgba="1 1 1 1" />
      </material>
    </visual>
    <collision>
      <origin
        xyz="0 0 0"
        rpy="0 0 0" />
      <geometry>
        <mesh
          filename="package://OneLeg2D/meshes/Foot_Link.STL" />
      </geometry>
    </collision>
  </link>
  <joint name="Foot_Joint" type="fixed">
    <origin xyz="0.17355 0 -0.3006" rpy="0 -0.5236 0" />
    <parent link="Knee_Link" />
    <child link="Foot_Link" />
    <axis xyz="0 0 1" />
  </joint>
</robot>